Workbook

Sheet customers
A1: customer_id | B1: full_name | C1: country | D1: signup_date
A2: C0001 | B2: Customer 1 | C2: UAE | D2: 2025-05-08
A3: C0002 | B3: Customer 2 | C3: France | D3: 2025-10-04
A4: C0003 | B4: Customer 3 | C4: Spain | D4: 2025-08-07
A5: C0004 | B5: Customer 4 | C5: Spain | D5: 2025-07-29
A6: C0005 | B6: Customer 5 | C6: France | D6: 2025-10-17
A7: C0006 | B7: Customer 6 | C7: USA | D7: 2025-12-16
A8: C0007 | B8: Customer 7 | C8: Germany | D8: 2025-03-15
A9: C0008 | B9: Customer 8 | C9: China | D9: 2025-10-31
A10: C0009 | B10: Customer 9 | C10: France | D10: 2025-02-18
A11: C0010 | B11: Customer_10 | C11: UAE | D11: 2025-05-19
A12: C0011 | B12: Customer 11 | C12: UK | D12: 2025-06-30
... A501: C0500 | B501: Customer_500 | C501: UK | D501: 2026-01-08

Sheet orders
A1: order_id | B1: customer_id | C1: sales_channel | D1: status | E1: order_date | F1: order_delay | G1: revenue_sales_channel
A2: O00001 | B2: C0127 | C2: Online | D2: Completed | E2: 2025-03-08 | F2: N/A | G2: =VLOOKUP(Table7_3[[#This Row],[order_id]], payments!$B$2:$G$1001, 4, FALSE) -> 1200
A3: O00002 | B3: C0242 | C3: Online | D3: Completed | E3: 2025-10-31 | F3: -28 | G3: =VLOOKUP(Table7_3[[#This Row],[order_id]], payments!$B$2:$G$1001, 4, FALSE) -> 800
A4: O00003 | B4: C0249 | C4: Store | D4: Completed | E4: 2026-01-01 | F4: -238 | G4: =VLOOKUP(Table7_3[[#This Row],[order_id]], payments!$B$2:$G$1001, 4, FALSE) -> 800
A5: O00004 | B5: C0146 | C5: Online | D5: Completed | E5: 2025-02-12 | F5: 125 | G5: =VLOOKUP(Table7_3[[#This Row],[order_id]], payments!$B$2:$G$1001, 4, FALSE) -> 500
A6: O00005 | B6: C0172 | C6: Store | D6: Completed | E6: 2026-01-30 | F6: -271 | G6: =VLOOKUP(Table7_3[[#This Row],[order_id]], payments!$B$2:$G$1001, 4, FALSE) -> 800
A7: O00006 | B7: C0319 | C7: Online | D7: Completed | E7: 2026-02-24 | F7: -175 | G7: =VLOOKUP(Table7_3[[#This Row],[order_id]], payments!$B$2:$G$1001, 4, FALSE) -> 1200
A8: O00007 | B8: C0218 | C8: Mobile | D8: Pending | E8: 2025-07-16 | F8: N/A | G8: =VLOOKUP(Table7_3[[#This Row],[order_id]], payments!$B$2:$G$1001, 4, FALSE) -> 2400
A9: O00008 | B9: C0194 | C9: Store | D9: Pending | E9: 2025-04-09 | F9: 99 | G9: =VLOOKUP(Table7_3[[#This Row],[order_id]], payments!$B$2:$G$1001, 4, FALSE) -> 800
A10: O00009 | B10: C0277 | C10: Online | D10: Pending | E10: 2025-09-24 | F10: 48 | G10: =VLOOKUP(Table7_3[[#This Row],[order_id]], payments!$B$2:$G$1001, 4, FALSE) -> 800
A11: O00010 | B11: C0421 | C11: Online | D11: Pending | E11: 2025-11-29 | F11: -185 | G11: =VLOOKUP(Table7_3[[#This Row],[order_id]], payments!$B$2:$G$1001, 4, FALSE) -> 1600
A12: O00011 | B12: C0399 | C12: Store | D12: Completed | E12: 2026-01-31 | F12: -317 | G12: =VLOOKUP(Table7_3[[#This Row],[order_id]], payments!$B$2:$G$1001, 4, FALSE) -> 2400
A13: O00012 | B13: C0048 | C13: Online | D13: Pending | E13: 2025-08-21 | F13: -221 | G13: =VLOOKUP(Table7_3[[#This Row],[order_id]], payments!$B$2:$G$1001, 4, FALSE) -> 800
A14: O00013 | B14: C0408 | C14: Mobile | D14: Completed | E14: 2025-07-31 | F14: 105 | G14: =VLOOKUP(Table7_3[[#This Row],[order_id]], payments!$B$2:$G$1001, 4, FALSE) -> 500
A15: O00014 | B15: C0224 | C15: Mobile | D15: Completed | E15: 2026-02-09 | F15: -307 | G15: =VLOOKUP(Table7_3[[#This Row],[order_id]], payments!$B$2:$G$1001, 4, FALSE) -> 1200
A16: O00015 | B16: C0234 | C16: Online | D16: Completed | E16: 2025-03-31 | F16: 261 | G16: =VLOOKUP(Table7_3[[#This Row],[order_id]], payments!$B$2:$G$1001, 4, FALSE) -> 1600
A17: O00016 | B17: C0191 | C17: Mobile | D17: Pending | E17: 2025-05-19 | F17: -90 | G17: =VLOOKUP(Table7_3[[#This Row],[order_id]], payments!$B$2:$G$1001, 4, FALSE) -> 500
A18: O00017 | B18: C0398 | C18: Mobile | D18: Completed | E18: 2025-06-21 | F18: 132 | G18: =VLOOKUP(Table7_3[[#This Row],[order_id]], payments!$B$2:$G$1001, 4, FALSE) -> 800
A19: O00018 | B19: C0335 | C19: Store | D19: Pending | E19: 2025-02-23 | F19: 171 | G19: =VLOOKUP(Table7_3[[#This Row],[order_id]], payments!$B$2:$G$1001, 4, FALSE) -> 2400
A20: O00019 | B20: C0288 | C20: Online | D20: Pending | E20: 2025-02-01 | F20: 6 | G20: =VLOOKUP(Table7_3[[#This Row],[order_id]], payments!$B$2:$G$1001, 4, FALSE) -> 800
... A23: O00022 | B23: C0148 | C23: Mobile | D23: Pending | E23: 2025-12-09 | F23: -293 | G23: =VLOOKUP(Table7_3[[#This Row],[order_id]], payments!$B$2:$G$1001, 4, FALSE) -> 2400
A24: O00023 | B24: C0112 | C24: Mobile | D24: Pending | E24: 2025-07-16 | F24: N/A | G24: =VLOOKUP(Table7_3[[#This Row],[order_id]], payments!$B$2:$G$1001, 4, FALSE) -> 800
A25: O00024 | B25: C0413 | C25: Online | D25: Pending | E25: 2025-09-16 | F25: -110 | G25: =VLOOKUP(Table7_3[[#This Row],[order_id]], payments!$B$2:$G$1001, 4, FALSE) -> 800
A26: O00025 | B26: C0357 | C26: Mobile | D26: Completed | E26: 2025-03-06 | F26: 17 | G26: =VLOOKUP(Table7_3[[#This Row],[order_id]], payments!$B$2:$G$1001, 4, FALSE) -> 1200
A27: O00026 | B27: C0280 | C27: Online | D27: Pending | E27: 2025-01-09 | F27: 89 | G27: =VLOOKUP(Table7_3[[#This Row],[order_id]], payments!$B$2:$G$1001, 4, FALSE) -> 800
A28: O00027 | B28: C0074 | C28: Online | D28: Completed | E28: 2025-06-07 | F28: N/A | G28: =VLOOKUP(Table7_3[[#This Row],[order_id]], payments!$B$2:$G$1001, 4, FALSE) -> 1200
A29: O00028 | B29: C0125 | C29: Online | D29: Pending | E29: 2025-09-09 | F29: -32 | G29: =VLOOKUP(Table7_3[[#This Row],[order_id]], payments!$B$2:$G$1001, 4, FALSE) -> 500
A30: O00029 | B30: C0414 | C30: Online | D30: Pending | E30: 2025-10-25 | F30: -78 | G30: =VLOOKUP(Table7_3[[#This Row],[order_id]], payments!$B$2:$G$1001, 4, FALSE) -> 2400
A31: O00030 | B31: C0401 | C31: Online | D31: Pending | E31: 2025-01-21 | F31: 88 | G31: =VLOOKUP(Table7_3[[#This Row],[order_id]], payments!$B$2:$G$1001, 4, FALSE) -> 800
A32: O00031 | B32: C0401 | C32: Mobile | D32: Completed | E32: 2025-01-18 | F32: 296 | G32: =VLOOKUP(Table7_3[[#This Row],[order_id]], payments!$B$2:$G$1001, 4, FALSE) -> 500
A33: O00032 | B33: C0054 | C33: Online | D33: Completed | E33: 2025-11-30 | F33: -101 | G33: =VLOOKUP(Table7_3[[#This Row],[order_id]], payments!$B$2:$G$1001, 4, FALSE) -> 800
A34: O00033 | B34: C0066 | C34: Online | D34: Pending | E34: 2025-08-19 | F34: N/A | G34: =VLOOKUP(Table7_3[[#This Row],[order_id]], payments!$B$2:$G$1001, 4, FALSE) -> 1200
A35: O00034 | B35: C0247 | C35: Online | D35: Completed | E35: 2025-11-20 | F35: -7 | G35: =VLOOKUP(Table7_3[[#This Row],[order_id]], payments!$B$2:$G$1001, 4, FALSE) -> 1600
A36: O00035 | B36: C0043 | C36: Online | D36: Pending | E36: 2026-02-15 | F36: N/A | G36: =VLOOKUP(Table7_3[[#This Row],[order_id]], payments!$B$2:$G$1001, 4, FALSE) -> 1200
A37: O00036 | B37: C0024 | C37: Store | D37: Completed | E37: 2025-07-16 | F37: 120 | G37: =VLOOKUP(Table7_3[[#This Row],[order_id]], payments!$B$2:$G$1001, 4, FALSE) -> 800
A38: O00037 | B38: C0288 | C38: Store | D38: Pending | E38: 2025-06-19 | F38: 246 | G38: =VLOOKUP(Table7_3[[#This Row],[order_id]], payments!$B$2:$G$1001, 4, FALSE) -> 500
A39: O00038 | B39: C0086 | C39: Online | D39: Completed | E39: 2025-04-01 | F39: -75 | G39: =VLOOKUP(Table7_3[[#This Row],[order_id]], payments!$B$2:$G$1001, 4, FALSE) -> 2400
A40: O00039 | B40: C0014 | C40: Online | D40: Completed | E40: 2025-04-24 | F40: 10 | G40: =VLOOKUP(Table7_3[[#This Row],[order_id]], payments!$B$2:$G$1001, 4, FALSE) -> 800
A41: O00040 | B41: C0187 | C41: Store | D41: Pending | E41: 2025-02-24 | F41: -16 | G41: =VLOOKUP(Table7_3[[#This Row],[order_id]], payments!$B$2:$G$1001, 4, FALSE) -> 800
A42: O00041 | B42: C0495 | C42: Online | D42: Completed | E42: 2025-03-18 | F42: 104 | G42: =VLOOKUP(Table7_3[[#This Row],[order_id]], payments!$B$2:$G$1001, 4, FALSE) -> 500
...

Sheet order_items
A1: order_item_id | B1: order_id | C1: product | D1: quantity | E1: price | F1: revenue | G1: negative_revenue_orders
A2: OI00001 | B2: O00275 | C2: Phone | D2: 2 | E2: 800 | F2: =D2*E2 -> 1600 | G2: =IF(F2<0, "NEGATIVE", "OK") -> OK
A3: OI00002 | B3: O00564 | C3: Tablet | D3: 1 | E3: 500 | F3: =D3*E3 -> 500 | G3: =IF(F3<0, "NEGATIVE", "OK") -> OK
A4: OI00003 | B4: O00317 | C4: Phone | D4: 3 | E4: 1200 | F4: =D4*E4 -> 3600 | G4: =IF(F4<0, "NEGATIVE", "OK") -> OK
A5: OI00004 | B5: O00297 | C5: Tablet | D5: -1 | E5: 1200 | F5: =D5*E5 -> -1200 | G5: =IF(F5<0, "NEGATIVE", "OK") -> NEGATIVE
A6: OI00005 | B6: O00196 | C6: Phone | D6: 2 | E6: 1200 | F6: =D6*E6 -> 2400 | G6: =IF(F6<0, "NEGATIVE", "OK") -> OK
A7: OI00006 | B7: O00873 | C7: Tablet | D7: 2 | E7: 500 | F7: =D7*E7 -> 1000 | G7: =IF(F7<0, "NEGATIVE", "OK") -> OK
A8: OI00007 | B8: O00944 | C8: Tablet | D8: 3 | E8: 1200 | F8: =D8*E8 -> 3600 | G8: =IF(F8<0, "NEGATIVE", "OK") -> OK
A9: OI00008 | B9: O00162 | C9: Phone | D9: 1 | E9: 1200 | F9: =D9*E9 -> 1200 | G9: =IF(F9<0, "NEGATIVE", "OK") -> OK
A10: OI00009 | B10: O00421 | C10: Phone | D10: 1 | E10: 800 | F10: =D10*E10 -> 800 | G10: =IF(F10<0, "NEGATIVE", "OK") -> OK
A11: OI00010 | B11: O00523 | C11: Laptop | D11: 3 | E11: 800 | F11: =D11*E11 -> 2400 | G11: =IF(F11<0, "NEGATIVE", "OK") -> OK
A12: OI00011 | B12: O00464 | C12: Laptop | D12: -1 | E12: 800 | F12: =D12*E12 -> -800 | G12: =IF(F12<0, "NEGATIVE", "OK") -> NEGATIVE
A13: OI00012 | B13: O00021 | C13: Phone | D13: 1 | E13: 1200 | F13: =D13*E13 -> 1200 | G13: =IF(F13<0, "NEGATIVE", "OK") -> OK
... A2001: OI02000 | B2001: O00075 | C2001: Laptop | D2001: -1 | E2001: 1200 | F2001: =D2001*E2001 -> -1200 | G2001: =IF(F2001<0, "NEGATIVE", "OK") -> NEGATIVE

Sheet payments
A1: payment_id | B1: order_id | C1: payment_date | D1: final_revenue | E1: amount | F1: status | G1: order_payment_dates_consistency
A2: P00001 | B2: O00372 | C2: N/A | D2: =IF(F2="PAID", E2, "N/A") -> N/A | E2: 1200 | F2: REFUNDED | G2: =IF(OR(Table7_3[[#This Row],[payment_date]]="N/A", Table3_5[[#This Row],[order_date]]="N/A"), "Inconsistent", IF(Table7_3[[#This Row],[payment_date]]>Table3_5[[#This Row],[order_date]], "Consistent", "Inconsistent")) -> Inconsistent
A3: P00002 | B3: O00467 | C3: 2025-10-03 | D3: =IF(F3="PAID", E3, "N/A") -> N/A | E3: 800 | F3: REFUNDED | G3: =IF(OR(Table7_3[[#This Row],[payment_date]]="N/A", Table3_5[[#This Row],[order_date]]="N/A"), "Inconsistent", IF(Table7_3[[#This Row],[payment_date]]>Table3_5[[#This Row],[order_date]], "Consistent", "Inconsistent")) -> Inconsistent
A4: P00003 | B4: O00251 | C4: 2025-05-08 | D4: =IF(F4="PAID", E4, "N/A") -> N/A | E4: 800 | F4: FAILED | G4: =IF(OR(Table7_3[[#This Row],[payment_date]]="N/A", Table3_5[[#This Row],[order_date]]="N/A"), "Inconsistent", IF(Table7_3[[#This Row],[payment_date]]>Table3_5[[#This Row],[order_date]], "Consistent", "Inconsistent")) -> Inconsistent
A5: P00004 | B5: O00333 | C5: 2025-06-17 | D5: =IF(F5="PAID", E5, "N/A") -> N/A | E5: 500 | F5: FAILED | G5: =IF(OR(Table7_3[[#This Row],[payment_date]]="N/A", Table3_5[[#This Row],[order_date]]="N/A"), "Inconsistent", IF(Table7_3[[#This Row],[payment_date]]>Table3_5[[#This Row],[order_date]], "Consistent", "Inconsistent")) -> Consistent
A6: P00005 | B6: O00316 | C6: 2025-05-04 | D6: =IF(F6="PAID", E6, "N/A") -> N/A | E6: 800 | F6: FAILED | G6: =IF(OR(Table7_3[[#This Row],[payment_date]]="N/A", Table3_5[[#This Row],[order_date]]="N/A"), "Inconsistent", IF(Table7_3[[#This Row],[payment_date]]>Table3_5[[#This Row],[order_date]], "Consistent", "Inconsistent")) -> Inconsistent
A7: P00006 | B7: O00772 | C7: 2025-09-02 | D7: =IF(F7="PAID", E7, "N/A") -> N/A | E7: 1200 | F7: REFUNDED | G7: =IF(OR(Table7_3[[#This Row],[payment_date]]="N/A", Table3_5[[#This Row],[order_date]]="N/A"), "Inconsistent", IF(Table7_3[[#This Row],[payment_date]]>Table3_5[[#This Row],[order_date]], "Consistent", "Inconsistent")) -> Inconsistent
A8: P00007 | B8: O00675 | C8: N/A | D8: =IF(F8="PAID", E8, "N/A") -> N/A | E8: 2400 | F8: REFUNDED | G8: =IF(OR(Table7_3[[#This Row],[payment_date]]="N/A", Table3_5[[#This Row],[order_date]]="N/A"), "Inconsistent", IF(Table7_3[[#This Row],[payment_date]]>Table3_5[[#This Row],[order_date]], "Consistent", "Inconsistent")) -> Inconsistent
A9: P00008 | B9: O00365 | C9: 2025-07-17 | D9: =IF(F9="PAID", E9, "N/A") -> N/A | E9: 800 | F9: FAILED | G9: =IF(OR(Table7_3[[#This Row],[payment_date]]="N/A", Table3_5[[#This Row],[order_date]]="N/A"), "Inconsistent", IF(Table7_3[[#This Row],[payment_date]]>Table3_5[[#This Row],[order_date]], "Consistent", "Inconsistent")) -> Consistent
A10: P00009 | B10: O00177 | C10: 2025-11-11 | D10: =IF(F10="PAID", E10, "N/A") -> N/A | E10: 800 | F10: FAILED | G10: =IF(OR(Table7_3[[#This Row],[payment_date]]="N/A", Table3_5[[#This Row],[order_date]]="N/A"), "Inconsistent", IF(Table7_3[[#This Row],[payment_date]]>Table3_5[[#This Row],[order_date]], "Consistent", "Inconsistent")) -> Consistent
A11: P00010 | B11: O00761 | C11: 2025-05-28 | D11: =IF(F11="PAID", E11, "N/A") -> 1600 | E11: 1600 | F11: PAID | G11: =IF(OR(Table7_3[[#This Row],[payment_date]]="N/A", Table3_5[[#This Row],[order_date]]="N/A"), "Inconsistent", IF(Table7_3[[#This Row],[payment_date]]>Table3_5[[#This Row],[order_date]], "Consistent", "Inconsistent")) -> Inconsistent
A12: P00011 | B12: O00256 | C12: 2025-03-20 | D12: =IF(F12="PAID", E12, "N/A") -> N/A | E12: 2400 | F12: REFUNDED | G12: =IF(OR(Table7_3[[#This Row],[payment_date]]="N/A", Table3_5[[#This Row],[order_date]]="N/A"), "Inconsistent", IF(Table7_3[[#This Row],[payment_date]]>Table3_5[[#This Row],[order_date]], "Consistent", "Inconsistent")) -> Inconsistent
A13: P00012 | B13: O00544 | C13: 2025-01-12 | D13: =IF(F13="PAID", E13, "N/A") -> N/A | E13: 800 | F13: REFUNDED | G13: =IF(OR(Table7_3[[#This Row],[payment_date]]="N/A", Table3_5[[#This Row],[order_date]]="N/A"), "Inconsistent", IF(Table7_3[[#This Row],[payment_date]]>Table3_5[[#This Row],[order_date]], "Consistent", "Inconsistent")) -> Inconsistent
... A1001: P01000 | B1001: O00278 | C1001: 2025-11-08 | D1001: =IF(F1001="PAID", E1001, "N/A") -> N/A | E1001: 800 | F1001: FAILED | G1001: =IF(OR(Table7_3[[#This Row],[payment_date]]="N/A", Table3_5[[#This Row],[order_date]]="N/A"), "Inconsistent", IF(Table7_3[[#This Row],[payment_date]]>Table3_5[[#This Row],[order_date]], "Consistent", "Inconsistent")) -> Inconsistent

Sheet support_tickets
A1: ticket_id | B1: customer_id | C1: order_id | D1: issue_type | E1: status | F1: created_date | G1: resolved_date
A2: T00001 | B2: C0106 | C2: O00189 | D2: Product | E2: Escalated | F2: 2025-08-21 | G2: 2025-08-25
A3: T00002 | B3: C0219 | C3: O00836 | D3: Delivery | E3: Resolved | F3: 2025-05-02 | G3: 2025-05-03
A4: T00003 | B4: C0001 | C4: O00540 | D4: Delivery | E4: Open | F4: 2026-02-18 | G4: N/A
A5: T00004 | B5: C0267 | C5: O00473 | D5: Product | E5: Escalated | F5: 2025-06-03 | G5: 2025-06-05
A6: T00005 | B6: C0198 | C6: O00563 | D6: Product | E6: Open | F6: 2025-08-14 | G6: N/A
A7: T00006 | B7: C0175 | C7: O00378 | D7: Delivery | E7: Resolved | F7: 2025-05-24 | G7: 2025-05-27
A8: T00007 | B8: C0386 | C8: O00562 | D8: Payment | E8: Escalated | F8: 2025-01-26 | G8: 2025-01-27
A9: T00008 | B9: C0304 | C9: O00994 | D9: Product | E9: Open | F9: 2026-01-16 | G9: 2026-01-19
A10: T00009 | B10: C0317 | C10: O00130 | D10: Payment | E10: Open | F10: 2025-07-05 | G10: 2025-07-07
A11: T00010 | B11: C0321 | C11: O00717 | D11: Delivery | E11: Resolved | F11: 2025-10-11 | G11: N/A
A12: T00011 | B12: C0275 | C12: O00098 | D12: Delivery | E12: Open | F12: 2025-07-21 | G12: 2025-07-23
... A1501: T01500 | B1501: C0077 | C1501: O00419 | D1501: Product | E1501: Escalated | F1501: 2025-09-16 | G1501: 2025-09-17

Sheet summary_metrics
B2: KPI section
B15: Pivot tables
C17: Revenue by sales channel | G17: Order Analysis | K17: Data Consistency | O17: Revenue Validation
C19: Row Labels | D19: Sum of revenue_sales_channel | G19: Row Labels | H19: Count of status | K19: Row Labels | L19: Count of order_payment_dates_consistency | O19: Row Labels | P19: Count of negative_revenue_orders
C20: Mobile | D20: 220000 | G20: Completed | H20: 508 | K20: Consistent | L20: 457 | O20: NEGATIVE | P20: 516
C21: Online | D21: 777700 | G21: Pending | H21: 492 | K21: Inconsistent | L21: 543 | O21: OK | P21: 1484
C22: Store | D22: 270000 | G22: (blank) | K22: (blank) | O22: (blank)
C23: (blank) | G23: Grand Total | H23: 1000 | K23: Grand Total | L23: 1000 | O23: Grand Total | P23: 2000
C24: Grand Total | D24: 1267700
